<?xml version="1.0" encoding="UTF-8"?>
<robot generator="Robot 3.2.2 (Python 3.8.6 on win32)" generated="20201004 11:51:07.918" rpa="false">
<suite id="s1" name="Checkout-Success" source="D:\IAMDEV\ShoppingCart\atdd\api-robot\checkout-success.robot">
<test id="s1-t1" name="Checkout Diner Set">
<kw name="Create Session" library="RequestsLibrary">
<doc>Create Session: create a HTTP session to a server</doc>
<arguments>
<arg>toy_store</arg>
<arg>http://localhost:8080</arg>
</arguments>
<msg timestamp="20201004 11:51:08.086" level="INFO">Creating Session using : alias=toy_store, url=http://localhost:8080, headers={},                     cookies={}, auth=None, timeout=None, proxies=None, verify=False,                     debug=0 </msg>
<status status="PASS" starttime="20201004 11:51:08.086" endtime="20201004 11:51:08.086"></status>
</kw>
<kw name="Create Dictionary" library="BuiltIn">
<doc>Creates and returns a dictionary based on the given ``items``.</doc>
<arguments>
<arg>Accept=application/json</arg>
</arguments>
<assign>
<var>&amp;{accept}</var>
</assign>
<msg timestamp="20201004 11:51:08.087" level="INFO">&amp;{accept} = { Accept=application/json }</msg>
<status status="PASS" starttime="20201004 11:51:08.087" endtime="20201004 11:51:08.087"></status>
</kw>
<kw name="Get Request" library="RequestsLibrary">
<doc>Send a GET request on the session object found using the
given `alias`</doc>
<arguments>
<arg>toy_store</arg>
<arg>/api/v1/product</arg>
<arg>headers=&amp;{accept}</arg>
</arguments>
<assign>
<var>${productlist}</var>
</assign>
<msg timestamp="20201004 11:51:10.372" level="WARN">Retrying (Retry(total=2, connect=None, read=None, redirect=None, status=None)) after connection broken by 'ProxyError('Cannot connect to proxy.', NewConnectionError('&lt;urllib3.connection.HTTPConnection object at 0x000001BEB626E3A0&gt;: Failed to establish a new connection: [Errno 11001] getaddrinfo failed'))': http://localhost:8080/api/v1/product</msg>
<msg timestamp="20201004 11:51:12.857" level="WARN">Retrying (Retry(total=1, connect=None, read=None, redirect=None, status=None)) after connection broken by 'ProxyError('Cannot connect to proxy.', NewConnectionError('&lt;urllib3.connection.HTTPConnection object at 0x000001BEB626E5B0&gt;: Failed to establish a new connection: [Errno 11001] getaddrinfo failed'))': http://localhost:8080/api/v1/product</msg>
<msg timestamp="20201004 11:51:15.539" level="WARN">Retrying (Retry(total=0, connect=None, read=None, redirect=None, status=None)) after connection broken by 'ProxyError('Cannot connect to proxy.', NewConnectionError('&lt;urllib3.connection.HTTPConnection object at 0x000001BEB626E790&gt;: Failed to establish a new connection: [Errno 11001] getaddrinfo failed'))': http://localhost:8080/api/v1/product</msg>
<msg timestamp="20201004 11:51:17.823" level="FAIL">ProxyError: HTTPConnectionPool(host='sahachan', port=80): Max retries exceeded with url: http://localhost:8080/api/v1/product (Caused by ProxyError('Cannot connect to proxy.', NewConnectionError('&lt;urllib3.connection.HTTPConnection object at 0x000001BEB626E970&gt;: Failed to establish a new connection: [Errno 11001] getaddrinfo failed')))</msg>
<status status="FAIL" starttime="20201004 11:51:08.088" endtime="20201004 11:51:17.823"></status>
</kw>
<status status="FAIL" starttime="20201004 11:51:08.084" endtime="20201004 11:51:17.824" critical="yes">ProxyError: HTTPConnectionPool(host='sahachan', port=80): Max retries exceeded with url: http://localhost:8080/api/v1/product (Caused by ProxyError('Cannot connect to proxy.', NewConnectionError('&lt;urllib3.connection.HTTPConnection object at 0x000001BEB626E970&gt;: Failed to establish a new connection: [Errno 11001] getaddrinfo failed')))</status>
</test>
<status status="FAIL" starttime="20201004 11:51:07.920" endtime="20201004 11:51:17.828"></status>
</suite>
<statistics>
<total>
<stat pass="0" fail="1">Critical Tests</stat>
<stat pass="0" fail="1">All Tests</stat>
</total>
<tag>
</tag>
<suite>
<stat pass="0" fail="1" id="s1" name="Checkout-Success">Checkout-Success</stat>
</suite>
</statistics>
<errors>
<msg timestamp="20201004 11:51:10.372" level="WARN">Retrying (Retry(total=2, connect=None, read=None, redirect=None, status=None)) after connection broken by 'ProxyError('Cannot connect to proxy.', NewConnectionError('&lt;urllib3.connection.HTTPConnection object at 0x000001BEB626E3A0&gt;: Failed to establish a new connection: [Errno 11001] getaddrinfo failed'))': http://localhost:8080/api/v1/product</msg>
<msg timestamp="20201004 11:51:12.857" level="WARN">Retrying (Retry(total=1, connect=None, read=None, redirect=None, status=None)) after connection broken by 'ProxyError('Cannot connect to proxy.', NewConnectionError('&lt;urllib3.connection.HTTPConnection object at 0x000001BEB626E5B0&gt;: Failed to establish a new connection: [Errno 11001] getaddrinfo failed'))': http://localhost:8080/api/v1/product</msg>
<msg timestamp="20201004 11:51:15.539" level="WARN">Retrying (Retry(total=0, connect=None, read=None, redirect=None, status=None)) after connection broken by 'ProxyError('Cannot connect to proxy.', NewConnectionError('&lt;urllib3.connection.HTTPConnection object at 0x000001BEB626E790&gt;: Failed to establish a new connection: [Errno 11001] getaddrinfo failed'))': http://localhost:8080/api/v1/product</msg>
</errors>
</robot>
